Workbook
Name fleet_telemetry_sample: '01_Raw_Data'!$A$1:$I$5001
Name Slicer_route_status: #N/A
Name Slicer_vessel_type: #N/A

Sheet 01_Raw_Data
A1: telemetry_id | B1: vessel_name | C1: vessel_type | D1: speed_knots | E1: beaufort_scale | F1: cargo_weight_tons | G1: route_status | H1: timestamp | I1: fuel_consumption_mt
A2: TEL-10000 | B2: MV Fleet_07 | C2: LNG Carrier | D2: 9.25 | E2: 3.0 | F2: 7736 | G2: Underway | H2: 2026-05-24 16:26:43.203853 | I2: 7.6
A3: TEL-10001 | B3: MV Fleet_20 | C3: Bulk Carrier | D3: 19.31 | E3: 3.0 | F3: 38724 | G3: Underway | H3: 2026-05-24 16:41:43.203853 | I3: 10.68
A4: TEL-10002 | B4: MV Fleet_15 | C4: LNG Carrier | D4: 22.72 | E4: 9.0 | F4: 16440 | G4: Underway | H4: 2026-05-24 16:56:43.203853 | I4: 22.6
A5: TEL-10003 | B5: MV Fleet_11 | C5: Bulk Carrier | D5: 12.33 | E5: 2.0 | F5: 10180 | G5: Underway | H5: 2026-05-24 17:11:43.203853 | I5: 3.75
A6: TEL-10004 | B6: MV Fleet_08 | C6: Bulk Carrier | D6: 13.93 | E6: 4.0 | F6: 35284 | G6: Anchored | H6: 2026-05-24 17:26:43.203853 | I6: 10.79
A7: TEL-10005 | B7: MV Fleet_07 | C7: LNG Carrier | D7: 17.1 | E7: 6.0 | F7: 46375 | G7: Underway | H7: 2026-05-24 17:41:43.203853 | I7: 14.0
A8: TEL-10006 | B8: MV Fleet_19 | C8: Bulk Carrier | D8: 22.11 | E8: 3.0 | F8: 16646 | G8: Underway | H8: 2026-05-24 17:56:43.203853 | I8: 13.87
A9: TEL-10007 | B9: MV Fleet_11 | C9: LNG Carrier | D9: 23.07 | E9: 7.0 | F9: 24029 | G9: Underway | H9: 2026-05-24 18:11:43.203853 | I9: 18.42
A10: TEL-10008 | B10: MV Fleet_11 | C10: Container | D10: 19.83 | E10: 7.0 | F10: 25158 | G10: Underway | H10: 2026-05-24 18:26:43.203853 | I10: 19.53
A11: TEL-10009 | B11: MV Fleet_04 | C11: LNG Carrier | D11: 9.39 | E11: 5.0 | F11: 19342 | G11: Underway | H11: 2026-05-24 18:41:43.203853 | I11: 10.1
A12: TEL-10010 | B12: MV Fleet_08 | C12: Container | D12: 18.71 | E12: 3.0 | F12: 42781 | G12: Moored | H12: 2026-05-24 18:56:43.203853 | I12: 8.96
A13: TEL-10011 | B13: MV Fleet_03 | C13: Bulk Carrier | D13: 14.56 | E13: 2.0 | F13: 5084 | G13: Underway | H13: 2026-05-24 19:11:43.203853 | I13: 8.49
... A30: TEL-10028 | B30: MV Fleet_05 | C30: LNG Carrier | D30: 13.86 | E30: 8.0 | F30: 39630 | G30: Moored | H30: 2026-05-24 23:26:43.203853 | I30: 16.96
A31: TEL-10029 | B31: MV Fleet_19 | C31: Bulk Carrier | D31: 20.91 | F31: 41994 | G31: Underway | H31: 2026-05-24 23:41:43.203853 | I31: 18.3
A32: TEL-10030 | B32: MV Fleet_07 | C32: Tanker | D32: 16.37 | E32: 2.0 | F32: 31339 | G32: Anchored | H32: 2026-05-24 23:56:43.203853 | I32: 7.39
A33: TEL-10031 | B33: MV Fleet_09 | C33: Tanker | D33: 9.87 | E33: 4.0 | F33: 35384 | G33: Underway | H33: 2026-05-25 00:11:43.203853 | I33: 8.27
A34: TEL-10032 | B34: MV Fleet_07 | C34: Container | D34: 10.07 | E34: 9.0 | F34: 46782 | G34: Underway | H34: 2026-05-25 00:26:43.203853 | I34: 14.15
A35: TEL-10033 | B35: MV Fleet_18 | C35: LNG Carrier | D35: 16.59 | E35: 5.0 | F35: 37643 | G35: Underway | H35: 2026-05-25 00:41:43.203853 | I35: 13.63
A36: TEL-10034 | B36: MV Fleet_04 | C36: Bulk Carrier | D36: 22.99 | E36: 3.0 | F36: 21926 | G36: Underway | H36: 2026-05-25 00:56:43.203853 | I36: 13.65
A37: TEL-10035 | B37: MV Fleet_14 | C37: LNG Carrier | D37: 12.93 | E37: 6.0 | F37: 43977 | G37: Moored | H37: 2026-05-25 01:11:43.203853 | I37: 13.6
A38: TEL-10036 | B38: MV Fleet_18 | C38: Bulk Carrier | D38: 21.91 | E38: 3.0 | F38: 28652 | G38: Underway | H38: 2026-05-25 01:26:43.203853 | I38: 15.35
A39: TEL-10037 | B39: MV Fleet_09 | C39: Container | D39: 20.23 | E39: 5.0 | F39: 15270 | G39: Underway | H39: 2026-05-25 01:41:43.203853 | I39: 14.64
A40: TEL-10038 | B40: MV Fleet_02 | C40: Bulk Carrier | D40: 11.96 | E40: 3.0 | F40: 22268 | G40: Underway | H40: 2026-05-25 01:56:43.203853 | I40: 6.79
A41: TEL-10039 | B41: MV Fleet_20 | C41: LNG Carrier | D41: 8.58 | E41: 6.0 | F41: 41417 | G41: Underway | H41: 2026-05-25 02:11:43.203853 | I41: 11.95
A42: TEL-10040 | B42: MV Fleet_15 | C42: LNG Carrier | D42: 9.63 | E42: 5.0 | F42: 25317 | G42: Underway | H42: 2026-05-25 02:26:43.203853 | I42: 8.5
A43: TEL-10041 | B43: MV Fleet_07 | C43: Container | D43: 19.66 | E43: 9.0 | F43: 41434 | G43: Underway | H43: 2026-05-25 02:41:43.203853 | I43: 20.52
... A66: TEL-10064 | B66: MV Fleet_08 | C66: Bulk Carrier | D66: 9.37 | E66: 1.0 | F66: 10493 | G66: Anchored | H66: 2026-05-25 08:26:43.203853 | I66: 3.52
A67: TEL-10065 | B67: MV Fleet_14 | C67: Bulk Carrier | D67: 15.2 | F67: 41645 | G67: Underway | H67: 2026-05-25 08:41:43.203853 | I67: 18.59
A68: TEL-10066 | B68: MV Fleet_08 | C68: Container | D68: 20.1 | E68: 6.0 | F68: 7282 | G68: Underway | H68: 2026-05-25 08:56:43.203853 | I68: 15.85
A69: TEL-10067 | B69: MV Fleet_16 | C69: Tanker | D69: 20.71 | E69: 1.0 | F69: 28170 | G69: Moored | H69: 2026-05-25 09:11:43.203853 | I69: 9.33
A70: TEL-10068 | B70: MV Fleet_13 | C70: LNG Carrier | D70: 15.91 | E70: 1.0 | F70: 49143 | G70: Underway | H70: 2026-05-25 09:26:43.203853 | I70: 8.6
A71: TEL-10069 | B71: MV Fleet_18 | C71: Container | D71: 22.32 | E71: 8.0 | F71: 6431 | G71: Underway | H71: 2026-05-25 09:41:43.203853 | I71: 17.08
A72: TEL-10070 | B72: MV Fleet_15 | C72: LNG Carrier | D72: 12.28 | E72: 6.0 | F72: 39543 | G72: Anchored | H72: 2026-05-25 09:56:43.203853 | I72: 11.08
A73: TEL-10071 | B73: MV Fleet_13 | C73: LNG Carrier | D73: 14.57 | E73: 8.0 | F73: 25591 | G73: Underway | H73: 2026-05-25 10:11:43.203853 | I73: 17.24
A74: TEL-10072 | B74: MV Fleet_09 | C74: Container | D74: 22.38 | E74: 8.0 | F74: 16351 | G74: Moored | H74: 2026-05-25 10:26:43.203853 | I74: 19.82
A75: TEL-10073 | B75: MV Fleet_15 | C75: Tanker | D75: 22.34 | E75: 8.0 | F75: 37483 | G75: Moored | H75: 2026-05-25 10:41:43.203853 | I75: 20.75
A76: TEL-10074 | B76: MV Fleet_13 | C76: LNG Carrier | D76: 18.97 | E76: 7.0 | F76: 36195 | G76: Underway | H76: 2026-05-25 10:56:43.203853 | I76: 16.17
A77: TEL-10075 | B77: MV Fleet_01 | C77: Container | D77: 21.74 | E77: 7.0 | F77: 42153 | G77: Moored | H77: 2026-05-25 11:11:43.203853 | I77: 20.35
A78: TEL-10076 | B78: MV Fleet_07 | C78: Bulk Carrier | D78: 9.42 | E78: 4.0 | F78: 27735 | G78: Moored | H78: 2026-05-25 11:26:43.203853 | I78: 9.55
...

Sheet 02_Cleaned_Data
A1: telemetry_id | B1: vessel_name | C1: vessel_type | D1: speed_knots | E1: beaufort_scale | F1: cargo_weight_tons | G1: route_status | H1: timestamp | I1: fuel_consumption_mt
A2: TEL-10000 | B2: MV Fleet_07 | C2: LNG Carrier | D2: 9.25 | E2: 3 | F2: 7736 | G2: Underway | H2: 2026-05-24 16:26:43.203853 | I2: 7.6
A3: TEL-10001 | B3: MV Fleet_20 | C3: Bulk Carrier | D3: 19.31 | E3: 3 | F3: 38724 | G3: Underway | H3: 2026-05-24 16:41:43.203853 | I3: 10.68
A4: TEL-10002 | B4: MV Fleet_15 | C4: LNG Carrier | D4: 22.72 | E4: 9 | F4: 16440 | G4: Underway | H4: 2026-05-24 16:56:43.203853 | I4: 22.6
A5: TEL-10003 | B5: MV Fleet_11 | C5: Bulk Carrier | D5: 12.33 | E5: 2 | F5: 10180 | G5: Underway | H5: 2026-05-24 17:11:43.203853 | I5: 3.75
A6: TEL-10004 | B6: MV Fleet_08 | C6: Bulk Carrier | D6: 13.93 | E6: 4 | F6: 35284 | G6: Anchored | H6: 2026-05-24 17:26:43.203853 | I6: 10.79
A7: TEL-10005 | B7: MV Fleet_07 | C7: LNG Carrier | D7: 17.1 | E7: 6 | F7: 46375 | G7: Underway | H7: 2026-05-24 17:41:43.203853 | I7: 14
A8: TEL-10006 | B8: MV Fleet_19 | C8: Bulk Carrier | D8: 22.11 | E8: 3 | F8: 16646 | G8: Underway | H8: 2026-05-24 17:56:43.203853 | I8: 13.87
A9: TEL-10007 | B9: MV Fleet_11 | C9: LNG Carrier | D9: 23.07 | E9: 7 | F9: 24029 | G9: Underway | H9: 2026-05-24 18:11:43.203853 | I9: 18.42
A10: TEL-10008 | B10: MV Fleet_11 | C10: Container | D10: 19.83 | E10: 7 | F10: 25158 | G10: Underway | H10: 2026-05-24 18:26:43.203853 | I10: 19.53
A11: TEL-10009 | B11: MV Fleet_04 | C11: LNG Carrier | D11: 9.39 | E11: 5 | F11: 19342 | G11: Underway | H11: 2026-05-24 18:41:43.203853 | I11: 10.1
A12: TEL-10010 | B12: MV Fleet_08 | C12: Container | D12: 18.71 | E12: 3 | F12: 42781 | G12: Moored | H12: 2026-05-24 18:56:43.203853 | I12: 8.96
A13: TEL-10011 | B13: MV Fleet_03 | C13: Bulk Carrier | D13: 14.56 | E13: 2 | F13: 5084 | G13: Underway | H13: 2026-05-24 19:11:43.203853 | I13: 8.49
... A5001: TEL-14999 | B5001: MV Fleet_17 | C5001: Container | D5001: 12.59 | E5001: 1 | F5001: 45459 | G5001: Anchored | H5001: 2026-07-15 18:11:43.203853 | I5001: 3.54

Sheet 03_Analytics_Formulas
A1: Vessel Type | B1: Total Telemetry Logs | C1: Avg Speed (Knots) | D1: Avg Fuel Consumption (MT) | E1: Avg Beaufort Weather
A2: Container | B2: =COUNTIF(CleanedFleetData[vessel_type], A2) -> 1240 | C2: =AVERAGEIF(CleanedFleetData[vessel_type], A2, CleanedFleetData[speed_knots]) -> 15.875032 | D2: =AVERAGEIFS(CleanedFleetData[fuel_consumption_mt], CleanedFleetData[vessel_type], A2) -> 12.071758 | E2: =AVERAGEIF(CleanedFleetData[vessel_type], A2, CleanedFleetData[beaufort_scale]) -> 4.9346774
A3: Bulk Carrier | B3: =COUNTIF(CleanedFleetData[vessel_type], A3) -> 1300 | C3: =AVERAGEIF(CleanedFleetData[vessel_type], A3, CleanedFleetData[speed_knots]) -> 15.863992 | D3: =AVERAGEIFS(CleanedFleetData[fuel_consumption_mt], CleanedFleetData[vessel_type], A3) -> 11.937323 | E3: =AVERAGEIF(CleanedFleetData[vessel_type], A3, CleanedFleetData[beaufort_scale]) -> 4.8084615
A4: Tanker | B4: =COUNTIF(CleanedFleetData[vessel_type], A4) -> 1246 | C4: =AVERAGEIF(CleanedFleetData[vessel_type], A4, CleanedFleetData[speed_knots]) -> 15.782271 | D4: =AVERAGEIFS(CleanedFleetData[fuel_consumption_mt], CleanedFleetData[vessel_type], A4) -> 12.035353 | E4: =AVERAGEIF(CleanedFleetData[vessel_type], A4, CleanedFleetData[beaufort_scale]) -> 4.9711075
A5: LNG Carrier | B5: =COUNTIF(CleanedFleetData[vessel_type], A5) -> 1214 | C5: =AVERAGEIF(CleanedFleetData[vessel_type], A5, CleanedFleetData[speed_knots]) -> 16.186862 | D5: =AVERAGEIFS(CleanedFleetData[fuel_consumption_mt], CleanedFleetData[vessel_type], A5) -> 12.490988 | E5: =AVERAGEIF(CleanedFleetData[vessel_type], A5, CleanedFleetData[beaufort_scale]) -> 5.1227348
A8: Search Telemetry ID | B8: TEL-10000
A9: Vessel Name | B9: =IFERROR(INDEX(CleanedFleetData[vessel_name], MATCH(B8, CleanedFleetData[telemetry_id], 0)), "Enter Valid ID") -> MV Fleet_07
A10: Fuel Consumed (MT) | B10: =IFERROR(INDEX(CleanedFleetData[fuel_consumption_mt], MATCH(B8, CleanedFleetData[telemetry_id], 0)), 0) -> 7.6

Sheet 04_AI_Training_Data
A1: Prompt / User Query | B1: Calculated Insight | C1: Ground Truth AI Response
A2: What is the average fuel consumption for Container vessels? | B2: ='03_Analytics_Formulas'!D2 -> 12.071758 | C2: ="Based on telemetry analytics, Container vessels have an average fuel consumption of " & TEXT('03_Analytics_Formulas'!D2, "0,00") & " MT per report." -> Based on telemetry analytics, Container vessels have an average fuel consumption of 12,07 MT per report.
A3: How many total telemetry records exist for LNG Carriers in the dataset? | B3: ='03_Analytics_Formulas'!B5 -> 1214 | C3: ="There are " & '03_Analytics_Formulas'!B5 & " verified telemetry entries recorded for LNG Carriers in the telemetry log." -> There are 1214 verified telemetry entries recorded for LNG Carriers in the telemetry log.
A4: What is the average operating speed of Bulk Carriers? | B4: ='03_Analytics_Formulas'!C3 -> 15.863992 | C4: ="The average recorded speed for Bulk Carriers across all reported routes is " & TEXT('03_Analytics_Formulas'!C3, "0,00") & " knots." -> The average recorded speed for Bulk Carriers across all reported routes is 15,86 knots.

Sheet 05_Executive_Dashboard
A1: Maritime Fleet Telemetry Analytics Dashboard
A3: Row Labels | B3: Average of fuel_consumption_mt | G3: Row Labels | H3: Count of telemetry_id
A4: 1 | B4: 6.2833627 | G4: Bulk Carrier | H4: 1300
A5: 2 | B5: 7.7669449 | G5: Container | H5: 1240
A6: 3 | B6: 9.3107566 | G6: LNG Carrier | H6: 1214
A7: 4 | B7: 10.658983 | G7: Tanker | H7: 1246
A8: 5 | B8: 12.036952 | G8: Grand Total | H8: 5000
A9: 6 | B9: 13.659482
A10: 7 | B10: 15.144244
A11: 8 | B11: 16.735035
A12: 9 | B12: 18.127074
A13: Grand Total | B13: 12.129522
